Workbook

Sheet Dashboard
B2: KOLLEKT.GG FINANCIAL TRACKER
B3: Pokemon TCG — Version 26.0
B5: NET POSITION | D5: TOTAL INVESTED | F5: TOTAL REVENUE | H5: ROI % | J5: ITEMS IN STOCK
B6: =Sales!S2-Purchases!J2 -> 39.6375 | D6: =Purchases!J2 -> 192.6 | F6: =Sales!S2 -> 232.2375 | H6: =IFERROR((Sales!S2-Purchases!J2)/Purchases!J2,0) -> 0.20580218 | J6: =COUNTIF(Purchases!H:H,"In Stock")+COUNTIF(Purchases!H:H,"Listed") -> 3
B9: PROFIT & LOSS | F9: SPENDING BREAKDOWN
B10: Total Revenue (Gross Sales) | C10: =IFERROR(SUMPRODUCT((LEN(Sales!E4:E1000)>0)*(Sales!G4:G1000*1)),0) -> 285 | F10: Sealed Products | G10: =SUMIFS(Purchases!I4:I1000,Purchases!C4:C1000,"Sealed Product") -> 115.85
B11: Less: Platform Fees | C11: =-IFERROR(SUMPRODUCT((LEN(Sales!E4:E1000)>0)*(Sales!I4:I1000*1)),0) -> -37.7625 | F11: Single Card Purchases | G11: =SUMIFS(Purchases!I4:I1000,Purchases!C4:C1000,"Single Card") -> 17.3
B12: Less: Shipping Costs (Sales) | C12: =-IFERROR(SUMPRODUCT((LEN(Sales!E4:E1000)>0)*(Sales!J4:J1000*1)),0) -> -15 | F12: Graded Card Purchases | G12: =SUMIFS(Purchases!I4:I1000,Purchases!C4:C1000,"Graded Card") -> 0
B13: Net Sales Revenue | C13: =C10+C11+C12 -> 232.2375 | F13: Supplies (Sleeves, Toploaders, etc) | G13: =SUMIFS(Purchases!I4:I1000,Purchases!C4:C1000,"Supplies") -> 14.45
F14: Shipping Materials | G14: =SUMIFS(Purchases!I4:I1000,Purchases!C4:C1000,"Shipping Materials") -> 0
B15: Cost of Goods Sold (COGS) | C15: =-IFERROR(SUMPRODUCT((LEN(Sales!E4:E1000)>0)*(Sales!L4:L1000*1)),0) -> -8.65 | F15: Grading Fees | G15: =SUMIFS(Purchases!I4:I1000,Purchases!C4:C1000,"Grading Fees") -> 45
B16: GROSS PROFIT | C16: =C13+C15 -> 223.5875 | F16: Other Expenses | G16: =SUMIFS(Purchases!I4:I1000,Purchases!C4:C1000,"Other Expense") -> 0
B18: Grading Fees | C18: =-SUMIFS(Purchases!I4:I1000,Purchases!C4:C1000,"Grading Fees") -> -45 | F18: TOTAL SPENDING | G18: =SUM(G10:G16) -> 192.6
B19: Supplies & Materials | C19: =-(SUMIFS(Purchases!I4:I1000,Purchases!C4:C1000,"Supplies")+SUMIFS(Purchases!I4:I1000,Purchases!C4:C1000,"Shipping Materials")) -> -14.45
B20: Other Expenses | C20: =-SUMIFS(Purchases!I4:I1000,Purchases!C4:C1000,"Other Expense") -> 0 | F20: Inventory Value (At Cost) | G20: =IFERROR(SUMPRODUCT((Purchases!H4:H1000="In Stock")*(Purchases!I4:I1000*1)),0)+IFERROR(SUMPRODUCT((Purchases!H4:H1000="Listed")*(Purchases!I4:I1000*1)),0) -> 107.25
B21: Total Operating Expenses | C21: =C18+C19+C20 -> -59.45 | F21: Items Sold | G21: =COUNTA(Sales!E4:E1000)-COUNTBLANK(Sales!E4:E1000) -> -995
F22: Items In Stock | G22: =COUNTIF(Purchases!H4:H1000,"In Stock")+COUNTIF(Purchases!H4:H1000,"Listed") -> 3
B23: NET PROFIT / (LOSS) | C23: =C16+C21 -> 164.1375 | F23: Avg Profit Per Sale | G23: =IFERROR(C23/G21,0) -> -0.16496231
B26: SALES BY PLATFORM | F26: MONTHLY TREND (Last 6 Months)
B27: eBay AU | C27: =COUNTIF(Sales!H4:H1000,B27) -> 1 | D27: =SUMIFS(Sales!K4:K1000,Sales!H4:H1000,B27) -> 232.2375 | F27: Month | G27: Purchases | H27: Sales | I27: Fees | J27: Net P/L | K27: Cum. P/L
B28: eBay US | C28: =COUNTIF(Sales!H4:H1000,B28) -> 0 | D28: =SUMIFS(Sales!K4:K1000,Sales!H4:H1000,B28) -> 0 | F28: =TEXT(EDATE(TODAY(),-5),"MMM YYYY") -> Sep 2025 | G28: =IFERROR(SUMPRODUCT((MONTH(Purchases!B4:B1000)=MONTH(EDATE(TODAY(),-5)))*(YEAR(Purchases!B4:B1000)=YEAR(EDATE(TODAY(),-5)))*(Purchases!I4:I1000*1)),0) -> 0 | H28: =IFERROR(SUMPRODUCT((MONTH(Sales!B4:B1000)=MONTH(EDATE(TODAY(),-5)))*(YEAR(Sales!B4:B1000)=YEAR(EDATE(TODAY(),-5)))*(Sales!K4:K1000*1)),0) -> 0 | I28: =IFERROR(SUMPRODUCT((MONTH(Sales!B4:B1000)=MONTH(EDATE(TODAY(),-5)))*(YEAR(Sales!B4:B1000)=YEAR(EDATE(TODAY(),-5)))*(Sales!I4:I1000*1)),0) -> 0 | J28: =H28-G28-I28 -> 0 | K28: =J28 -> 0
B29: Whatnot | C29: =COUNTIF(Sales!H4:H1000,B29) -> 0 | D29: =SUMIFS(Sales!K4:K1000,Sales!H4:H1000,B29) -> 0 | F29: =TEXT(EDATE(TODAY(),-4),"MMM YYYY") -> Oct 2025 | G29: =IFERROR(SUMPRODUCT((MONTH(Purchases!B4:B1000)=MONTH(EDATE(TODAY(),-4)))*(YEAR(Purchases!B4:B1000)=YEAR(EDATE(TODAY(),-4)))*(Purchases!I4:I1000*1)),0) -> 0 | H29: =IFERROR(SUMPRODUCT((MONTH(Sales!B4:B1000)=MONTH(EDATE(TODAY(),-4)))*(YEAR(Sales!B4:B1000)=YEAR(EDATE(TODAY(),-4)))*(Sales!K4:K1000*1)),0) -> 0 | I29: =IFERROR(SUMPRODUCT((MONTH(Sales!B4:B1000)=MONTH(EDATE(TODAY(),-4)))*(YEAR(Sales!B4:B1000)=YEAR(EDATE(TODAY(),-4)))*(Sales!I4:I1000*1)),0) -> 0 | J29: =H29-G29-I29 -> 0 | K29: =K28+J29 -> 0
B30: Facebook Marketplace | C30: =COUNTIF(Sales!H4:H1000,B30) -> 0 | D30: =SUMIFS(Sales!K4:K1000,Sales!H4:H1000,B30) -> 0 | F30: =TEXT(EDATE(TODAY(),-3),"MMM YYYY") -> Nov 2025 | G30: =IFERROR(SUMPRODUCT((MONTH(Purchases!B4:B1000)=MONTH(EDATE(TODAY(),-3)))*(YEAR(Purchases!B4:B1000)=YEAR(EDATE(TODAY(),-3)))*(Purchases!I4:I1000*1)),0) -> 0 | H30: =IFERROR(SUMPRODUCT((MONTH(Sales!B4:B1000)=MONTH(EDATE(TODAY(),-3)))*(YEAR(Sales!B4:B1000)=YEAR(EDATE(TODAY(),-3)))*(Sales!K4:K1000*1)),0) -> 0 | I30: =IFERROR(SUMPRODUCT((MONTH(Sales!B4:B1000)=MONTH(EDATE(TODAY(),-3)))*(YEAR(Sales!B4:B1000)=YEAR(EDATE(TODAY(),-3)))*(Sales!I4:I1000*1)),0) -> 0 | J30: =H30-G30-I30 -> 0 | K30: =K29+J30 -> 0
B31: TCGPlayer | C31: =COUNTIF(Sales!H4:H1000,B31) -> 0 | D31: =SUMIFS(Sales!K4:K1000,Sales!H4:H1000,B31) -> 0 | F31: =TEXT(EDATE(TODAY(),-2),"MMM YYYY") -> Dec 2025 | G31: =IFERROR(SUMPRODUCT((MONTH(Purchases!B4:B1000)=MONTH(EDATE(TODAY(),-2)))*(YEAR(Purchases!B4:B1000)=YEAR(EDATE(TODAY(),-2)))*(Purchases!I4:I1000*1)),0) -> 0 | H31: =IFERROR(SUMPRODUCT((MONTH(Sales!B4:B1000)=MONTH(EDATE(TODAY(),-2)))*(YEAR(Sales!B4:B1000)=YEAR(EDATE(TODAY(),-2)))*(Sales!K4:K1000*1)),0) -> 0 | I31: =IFERROR(SUMPRODUCT((MONTH(Sales!B4:B1000)=MONTH(EDATE(TODAY(),-2)))*(YEAR(Sales!B4:B1000)=YEAR(EDATE(TODAY(),-2)))*(Sales!I4:I1000*1)),0) -> 0 | J31: =H31-G31-I31 -> 0 | K31: =K30+J31 -> 0
B32: Gumtree | C32: =COUNTIF(Sales!H4:H1000,B32) -> 0 | D32: =SUMIFS(Sales!K4:K1000,Sales!H4:H1000,B32) -> 0 | F32: =TEXT(EDATE(TODAY(),-1),"MMM YYYY") -> Jan 2026 | G32: =IFERROR(SUMPRODUCT((MONTH(Purchases!B4:B1000)=MONTH(EDATE(TODAY(),-1)))*(YEAR(Purchases!B4:B1000)=YEAR(EDATE(TODAY(),-1)))*(Purchases!I4:I1000*1)),0) -> 0 | H32: =IFERROR(SUMPRODUCT((MONTH(Sales!B4:B1000)=MONTH(EDATE(TODAY(),-1)))*(YEAR(Sales!B4:B1000)=YEAR(EDATE(TODAY(),-1)))*(Sales!K4:K1000*1)),0) -> 0 | I32: =IFERROR(SUMPRODUCT((MONTH(Sales!B4:B1000)=MONTH(EDATE(TODAY(),-1)))*(YEAR(Sales!B4:B1000)=YEAR(EDATE(TODAY(),-1)))*(Sales!I4:I1000*1)),0) -> 0 | J32: =H32-G32-I32 -> 0 | K32: =K31+J32 -> 0
B33: Mercari | C33: =COUNTIF(Sales!H4:H1000,B33) -> 0 | D33: =SUMIFS(Sales!K4:K1000,Sales!H4:H1000,B33) -> 0 | F33: =TEXT(EDATE(TODAY(),-0),"MMM YYYY") -> Feb 2026 | G33: =IFERROR(SUMPRODUCT((MONTH(Purchases!B4:B1000)=MONTH(EDATE(TODAY(),-0)))*(YEAR(Purchases!B4:B1000)=YEAR(EDATE(TODAY(),-0)))*(Purchases!I4:I1000*1)),0) -> 192.6 | H33: =IFERROR(SUMPRODUCT((MONTH(Sales!B4:B1000)=MONTH(EDATE(TODAY(),-0)))*(YEAR(Sales!B4:B1000)=YEAR(EDATE(TODAY(),-0)))*(Sales!K4:K1000*1)),0) -> 232.2375 | I33: =IFERROR(SUMPRODUCT((MONTH(Sales!B4:B1000)=MONTH(EDATE(TODAY(),-0)))*(YEAR(Sales!B4:B1000)=YEAR(EDATE(TODAY(),-0)))*(Sales!I4:I1000*1)),0) -> 37.7625 | J33: =H33-G33-I33 -> 1.875 | K33: =K32+J33 -> 1.875
B34: CardMarket | C34: =COUNTIF(Sales!H4:H1000,B34) -> 0 | D34: =SUMIFS(Sales!K4:K1000,Sales!H4:H1000,B34) -> 0
B35: Direct/Local | C35: =COUNTIF(Sales!H4:H1000,B35) -> 0 | D35: =SUMIFS(Sales!K4:K1000,Sales!H4:H1000,B35) -> 0
B36: Other | C36: =COUNTIF(Sales!H4:H1000,B36) -> 0 | D36: =SUMIFS(Sales!K4:K1000,Sales!H4:H1000,B36) -> 0
B40: kollekt.gg — The Everyday Australian Collector | Data refreshes automatically from Purchases & Sales tabs

Sheet Purchases
A1: PURCHASES — Money Out
H2: TOTAL SPENT: | J2: =SUM(I4:I1000) -> 192.6
A3: ID | B3: Date | C3: Category | D3: Description | E3: Set / Series | F3: Qty | G3: Unit Cost | H3: Status | I3: Total Cost | J3: Source | K3: Parent ID | L3: Notes | M3: Market Price | N3: Market Value
A4: =IF(B4="","",ROW()-3) -> 1 | B4: 46054 | C4: Sealed Product | D4: Ascended Heroes ETB | E4: Ascended Heroes | F4: 1 | G4: 89.95 | H4: In Stock | I4: =IF(F4="",0,F4*G4) -> 89.95 | J4: EB Games | L4: First ETB for content | N4: =IF(AND(M4<>"",F4<>""),F4*M4,"")
A5: =IF(B5="","",ROW()-3) -> 2 | B5: 46054 | C5: Sealed Product | D5: Ascended Heroes Mini Tin x2 | E5: Ascended Heroes | F5: 2 | G5: 12.95 | H5: Opened | I5: =IF(F5="",0,F5*G5) -> 25.9 | J5: Good Games | L5: Opened on camera | N5: =IF(AND(M5<>"",F5<>""),F5*M5,"")
A6: =IF(B6="","",ROW()-3) -> 3 | B6: 46056 | C6: Single Card | D6: Erika Full Art SAR | E6: Ascended Heroes | F6: 1 | G6: 8.65 | H6: Listed | I6: =IF(F6="",0,F6*G6) -> 8.65 | J6: Pulled from Mini Tin | K6: 2 | L6: Parent: Mini Tin purchase | N6: =IF(AND(M6<>"",F6<>""),F6*M6,"")
A7: =IF(B7="","",ROW()-3) -> 4 | B7: 46056 | C7: Single Card | D7: Charizard ex | E7: Ascended Heroes | F7: 1 | G7: 8.65 | H7: In Stock | I7: =IF(F7="",0,F7*G7) -> 8.65 | J7: Pulled from Mini Tin | K7: 2 | L7: Parent: Mini Tin purchase | N7: =IF(AND(M7<>"",F7<>""),F7*M7,"")
A8: =IF(B8="","",ROW()-3) -> 5 | B8: 46058 | C8: Supplies | D8: Ultra Pro Penny Sleeves (100) | F8: 1 | G8: 5.5 | H8: Used | I8: =IF(F8="",0,F8*G8) -> 5.5 | J8: Amazon AU | N8: =IF(AND(M8<>"",F8<>""),F8*M8,"")
A9: =IF(B9="","",ROW()-3) -> 6 | B9: 46058 | C9: Supplies | D9: Ultra Pro Toploaders (25) | F9: 1 | G9: 8.95 | H9: Used | I9: =IF(F9="",0,F9*G9) -> 8.95 | J9: Amazon AU | N9: =IF(AND(M9<>"",F9<>""),F9*M9,"")
A10: =IF(B10="","",ROW()-3) -> 7 | B10: 46063 | C10: Grading Fees | D10: PSA Grading - Erika SAR | F10: 1 | G10: 45 | H10: Used | I10: =IF(F10="",0,F10*G10) -> 45 | J10: PSA | K10: 3 | L10: Submitted for grading | N10: =IF(AND(M10<>"",F10<>""),F10*M10,"")
A11: =IF(B11="","",ROW()-3) | I11: =IF(F11="",0,F11*G11) -> 0 | N11: =IF(AND(M11<>"",F11<>""),F11*M11,"")
A12: =IF(B12="","",ROW()-3) | I12: =IF(F12="",0,F12*G12) -> 0 | N12: =IF(AND(M12<>"",F12<>""),F12*M12,"")
A13: =IF(B13="","",ROW()-3) | I13: =IF(F13="",0,F13*G13) -> 0 | N13: =IF(AND(M13<>"",F13<>""),F13*M13,"")
A14: =IF(B14="","",ROW()-3) | I14: =IF(F14="",0,F14*G14) -> 0 | N14: =IF(AND(M14<>"",F14<>""),F14*M14,"")
A15: =IF(B15="","",ROW()-3) | I15: =IF(F15="",0,F15*G15) -> 0 | N15: =IF(AND(M15<>"",F15<>""),F15*M15,"")
A16: =IF(B16="","",ROW()-3) | I16: =IF(F16="",0,F16*G16) -> 0 | N16: =IF(AND(M16<>"",F16<>""),F16*M16,"")
A17: =IF(B17="","",ROW()-3) | I17: =IF(F17="",0,F17*G17) -> 0 | N17: =IF(AND(M17<>"",F17<>""),F17*M17,"")
A18: =IF(B18="","",ROW()-3) | I18: =IF(F18="",0,F18*G18) -> 0 | N18: =IF(AND(M18<>"",F18<>""),F18*M18,"")
A19: =IF(B19="","",ROW()-3) | I19: =IF(F19="",0,F19*G19) -> 0 | N19: =IF(AND(M19<>"",F19<>""),F19*M19,"")
A20: =IF(B20="","",ROW()-3) | I20: =IF(F20="",0,F20*G20) -> 0 | N20: =IF(AND(M20<>"",F20<>""),F20*M20,"")
A21: =IF(B21="","",ROW()-3) | I21: =IF(F21="",0,F21*G21) -> 0 | N21: =IF(AND(M21<>"",F21<>""),F21*M21,"")
A22: =IF(B22="","",ROW()-3) | I22: =IF(F22="",0,F22*G22) -> 0 | N22: =IF(AND(M22<>"",F22<>""),F22*M22,"")
... A1000: =IF(B1000="","",ROW()-3) | I1000: =IF(F1000="",0,F1000*G1000) -> 0 | N1000: =IF(AND(M1000<>"",F1000<>""),F1000*M1000,"")

Sheet Sales
A1: SALES — Money In
R2: NET REVENUE: | S2: =SUM(K4:K1000) -> 232.2375
A3: ID | B3: Date Sold | C3: Category | D3: Description | E3: Set / Series | F3: Qty | G3: Sale Price | H3: Platform | I3: Platform Fee $ | J3: Shipping Cost | K3: Net Revenue | L3: COGS | M3: Profit / Loss | N3: Margin % | O3: Purchase Ref ID | P3: Buyer | Q3: Tracking # | R3: Notes | S3: Fee % Used
A4: =IF(B4="","",ROW()-3) -> 1 | B4: 46068 | C4: Graded Card | D4: Erika Full Art SAR PSA 10 | E4: Ascended Heroes | F4: 1 | G4: 285 | H4: eBay AU | I4: =IF(G4="",0,G4*S4) -> 37.7625 | J4: 15 | K4: =IF(G4="",0,G4-I4-IF(J4="",0,J4)) -> 232.2375 | L4: =IF(O4="",0,IFERROR(INDEX(Purchases!I:I,MATCH(O4*1,Purchases!A:A,0)),0)) -> 8.65 | M4: =IF(G4="",0,K4-L4) -> 223.5875 | N4: =IFERROR(IF(G4="","",M4/G4),"") -> 0.78451754 | O4: 3 | P4: PokeFan123 | Q4: AU1234567890 | R4: First big sale! | S4: =IFERROR(VLOOKUP(H4,Settings!B14:C25,2,FALSE()),0) -> 0.1325
A5: =IF(B5="","",ROW()-3) | I5: =IF(G5="",0,G5*S5) -> 0 | K5: =IF(G5="",0,G5-I5-IF(J5="",0,J5)) -> 0 | L5: =IF(O5="",0,IFERROR(INDEX(Purchases!I:I,MATCH(O5*1,Purchases!A:A,0)),0)) -> 0 | M5: =IF(G5="",0,K5-L5) -> 0 | N5: =IFERROR(IF(G5="","",M5/G5),"") | S5: =IFERROR(VLOOKUP(H5,Settings!B14:C25,2,FALSE()),0) -> 0
A6: =IF(B6="","",ROW()-3) | I6: =IF(G6="",0,G6*S6) -> 0 | K6: =IF(G6="",0,G6-I6-IF(J6="",0,J6)) -> 0 | L6: =IF(O6="",0,IFERROR(INDEX(Purchases!I:I,MATCH(O6*1,Purchases!A:A,0)),0)) -> 0 | M6: =IF(G6="",0,K6-L6) -> 0 | N6: =IFERROR(IF(G6="","",M6/G6),"") | S6: =IFERROR(VLOOKUP(H6,Settings!B14:C25,2,FALSE()),0) -> 0
A7: =IF(B7="","",ROW()-3) | I7: =IF(G7="",0,G7*S7) -> 0 | K7: =IF(G7="",0,G7-I7-IF(J7="",0,J7)) -> 0 | L7: =IF(O7="",0,IFERROR(INDEX(Purchases!I:I,MATCH(O7*1,Purchases!A:A,0)),0)) -> 0 | M7: =IF(G7="",0,K7-L7) -> 0 | N7: =IFERROR(IF(G7="","",M7/G7),"") | S7: =IFERROR(VLOOKUP(H7,Settings!B14:C25,2,FALSE()),0) -> 0
A8: =IF(B8="","",ROW()-3) | I8: =IF(G8="",0,G8*S8) -> 0 | K8: =IF(G8="",0,G8-I8-IF(J8="",0,J8)) -> 0 | L8: =IF(O8="",0,IFERROR(INDEX(Purchases!I:I,MATCH(O8*1,Purchases!A:A,0)),0)) -> 0 | M8: =IF(G8="",0,K8-L8) -> 0 | N8: =IFERROR(IF(G8="","",M8/G8),"") | S8: =IFERROR(VLOOKUP(H8,Settings!B14:C25,2,FALSE()),0) -> 0
A9: =IF(B9="","",ROW()-3) | I9: =IF(G9="",0,G9*S9) -> 0 | K9: =IF(G9="",0,G9-I9-IF(J9="",0,J9)) -> 0 | L9: =IF(O9="",0,IFERROR(INDEX(Purchases!I:I,MATCH(O9*1,Purchases!A:A,0)),0)) -> 0 | M9: =IF(G9="",0,K9-L9) -> 0 | N9: =IFERROR(IF(G9="","",M9/G9),"") | S9: =IFERROR(VLOOKUP(H9,Settings!B14:C25,2,FALSE()),0) -> 0
A10: =IF(B10="","",ROW()-3) | I10: =IF(G10="",0,G10*S10) -> 0 | K10: =IF(G10="",0,G10-I10-IF(J10="",0,J10)) -> 0 | L10: =IF(O10="",0,IFERROR(INDEX(Purchases!I:I,MATCH(O10*1,Purchases!A:A,0)),0)) -> 0 | M10: =IF(G10="",0,K10-L10) -> 0 | N10: =IFERROR(IF(G10="","",M10/G10),"") | S10: =IFERROR(VLOOKUP(H10,Settings!B14:C25,2,FALSE()),0) -> 0
A11: =IF(B11="","",ROW()-3) | I11: =IF(G11="",0,G11*S11) -> 0 | K11: =IF(G11="",0,G11-I11-IF(J11="",0,J11)) -> 0 | L11: =IF(O11="",0,IFERROR(INDEX(Purchases!I:I,MATCH(O11*1,Purchases!A:A,0)),0)) -> 0 | M11: =IF(G11="",0,K11-L11) -> 0 | N11: =IFERROR(IF(G11="","",M11/G11),"") | S11: =IFERROR(VLOOKUP(H11,Settings!B14:C25,2,FALSE()),0) -> 0
A12: =IF(B12="","",ROW()-3) | I12: =IF(G12="",0,G12*S12) -> 0 | K12: =IF(G12="",0,G12-I12-IF(J12="",0,J12)) -> 0 | L12: =IF(O12="",0,IFERROR(INDEX(Purchases!I:I,MATCH(O12*1,Purchases!A:A,0)),0)) -> 0 | M12: =IF(G12="",0,K12-L12) -> 0 | N12: =IFERROR(IF(G12="","",M12/G12),"") | S12: =IFERROR(VLOOKUP(H12,Settings!B14:C25,2,FALSE()),0) -> 0
A13: =IF(B13="","",ROW()-3) | I13: =IF(G13="",0,G13*S13) -> 0 | K13: =IF(G13="",0,G13-I13-IF(J13="",0,J13)) -> 0 | L13: =IF(O13="",0,IFERROR(INDEX(Purchases!I:I,MATCH(O13*1,Purchases!A:A,0)),0)) -> 0 | M13: =IF(G13="",0,K13-L13) -> 0 | N13: =IFERROR(IF(G13="","",M13/G13),"") | S13: =IFERROR(VLOOKUP(H13,Settings!B14:C25,2,FALSE()),0) -> 0
A14: =IF(B14="","",ROW()-3) | I14: =IF(G14="",0,G14*S14) -> 0 | K14: =IF(G14="",0,G14-I14-IF(J14="",0,J14)) -> 0 | L14: =IF(O14="",0,IFERROR(INDEX(Purchases!I:I,MATCH(O14*1,Purchases!A:A,0)),0)) -> 0 | M14: =IF(G14="",0,K14-L14) -> 0 | N14: =IFERROR(IF(G14="","",M14/G14),"") | S14: =IFERROR(VLOOKUP(H14,Settings!B14:C25,2,FALSE()),0) -> 0
A15: =IF(B15="","",ROW()-3) | I15: =IF(G15="",0,G15*S15) -> 0 | K15: =IF(G15="",0,G15-I15-IF(J15="",0,J15)) -> 0 | L15: =IF(O15="",0,IFERROR(INDEX(Purchases!I:I,MATCH(O15*1,Purchases!A:A,0)),0)) -> 0 | M15: =IF(G15="",0,K15-L15) -> 0 | N15: =IFERROR(IF(G15="","",M15/G15),"") | S15: =IFERROR(VLOOKUP(H15,Settings!B14:C25,2,FALSE()),0) -> 0
A16: =IF(B16="","",ROW()-3) | I16: =IF(G16="",0,G16*S16) -> 0 | K16: =IF(G16="",0,G16-I16-IF(J16="",0,J16)) -> 0 | L16: =IF(O16="",0,IFERROR(INDEX(Purchases!I:I,MATCH(O16*1,Purchases!A:A,0)),0)) -> 0 | M16: =IF(G16="",0,K16-L16) -> 0 | N16: =IFERROR(IF(G16="","",M16/G16),"") | S16: =IFERROR(VLOOKUP(H16,Settings!B14:C25,2,FALSE()),0) -> 0
A17: =IF(B17="","",ROW()-3) | I17: =IF(G17="",0,G17*S17) -> 0 | K17: =IF(G17="",0,G17-I17-IF(J17="",0,J17)) -> 0 | L17: =IF(O17="",0,IFERROR(INDEX(Purchases!I:I,MATCH(O17*1,Purchases!A:A,0)),0)) -> 0 | M17: =IF(G17="",0,K17-L17) -> 0 | N17: =IFERROR(IF(G17="","",M17/G17),"") | S17: =IFERROR(VLOOKUP(H17,Settings!B14:C25,2,FALSE()),0) -> 0
A18: =IF(B18="","",ROW()-3) | I18: =IF(G18="",0,G18*S18) -> 0 | K18: =IF(G18="",0,G18-I18-IF(J18="",0,J18)) -> 0 | L18: =IF(O18="",0,IFERROR(INDEX(Purchases!I:I,MATCH(O18*1,Purchases!A:A,0)),0)) -> 0 | M18: =IF(G18="",0,K18-L18) -> 0 | N18: =IFERROR(IF(G18="","",M18/G18),"") | S18: =IFERROR(VLOOKUP(H18,Settings!B14:C25,2,FALSE()),0) -> 0
A19: =IF(B19="","",ROW()-3) | I19: =IF(G19="",0,G19*S19) -> 0 | K19: =IF(G19="",0,G19-I19-IF(J19="",0,J19)) -> 0 | L19: =IF(O19="",0,IFERROR(INDEX(Purchases!I:I,MATCH(O19*1,Purchases!A:A,0)),0)) -> 0 | M19: =IF(G19="",0,K19-L19) -> 0 | N19: =IFERROR(IF(G19="","",M19/G19),"") | S19: =IFERROR(VLOOKUP(H19,Settings!B14:C25,2,FALSE()),0) -> 0
A20: =IF(B20="","",ROW()-3) | I20: =IF(G20="",0,G20*S20) -> 0 | K20: =IF(G20="",0,G20-I20-IF(J20="",0,J20)) -> 0 | L20: =IF(O20="",0,IFERROR(INDEX(Purchases!I:I,MATCH(O20*1,Purchases!A:A,0)),0)) -> 0 | M20: =IF(G20="",0,K20-L20) -> 0 | N20: =IFERROR(IF(G20="","",M20/G20),"") | S20: =IFERROR(VLOOKUP(H20,Settings!B14:C25,2,FALSE()),0) -> 0
A21: =IF(B21="","",ROW()-3) | I21: =IF(G21="",0,G21*S21) -> 0 | K21: =IF(G21="",0,G21-I21-IF(J21="",0,J21)) -> 0 | L21: =IF(O21="",0,IFERROR(INDEX(Purchases!I:I,MATCH(O21*1,Purchases!A:A,0)),0)) -> 0 | M21: =IF(G21="",0,K21-L21) -> 0 | N21: =IFERROR(IF(G21="","",M21/G21),"") | S21: =IFERROR(VLOOKUP(H21,Settings!B14:C25,2,FALSE()),0) -> 0
A22: =IF(B22="","",ROW()-3) | I22: =IF(G22="",0,G22*S22) -> 0 | K22: =IF(G22="",0,G22-I22-IF(J22="",0,J22)) -> 0 | L22: =IF(O22="",0,IFERROR(INDEX(Purchases!I:I,MATCH(O22*1,Purchases!A:A,0)),0)) -> 0 | M22: =IF(G22="",0,K22-L22) -> 0 | N22: =IFERROR(IF(G22="","",M22/G22),"") | S22: =IFERROR(VLOOKUP(H22,Settings!B14:C25,2,FALSE()),0) -> 0
A23: =IF(B23="","",ROW()-3) | I23: =IF(G23="",0,G23*S23) -> 0 | K23: =IF(G23="",0,G23-I23-IF(J23="",0,J23)) -> 0 | L23: =IF(O23="",0,IFERROR(INDEX(Purchases!I:I,MATCH(O23*1,Purchases!A:A,0)),0)) -> 0 | M23: =IF(G23="",0,K23-L23) -> 0 | N23: =IFERROR(IF(G23="","",M23/G23),"") | S23: =IFERROR(VLOOKUP(H23,Settings!B14:C25,2,FALSE()),0) -> 0
A24: =IF(B24="","",ROW()-3) | I24: =IF(G24="",0,G24*S24) -> 0 | K24: =IF(G24="",0,G24-I24-IF(J24="",0,J24)) -> 0 | L24: =IF(O24="",0,IFERROR(INDEX(Purchases!I:I,MATCH(O24*1,Purchases!A:A,0)),0)) -> 0 | M24: =IF(G24="",0,K24-L24) -> 0 | N24: =IFERROR(IF(G24="","",M24/G24),"") | S24: =IFERROR(VLOOKUP(H24,Settings!B14:C25,2,FALSE()),0) -> 0
A25: =IF(B25="","",ROW()-3) | I25: =IF(G25="",0,G25*S25) -> 0 | K25: =IF(G25="",0,G25-I25-IF(J25="",0,J25)) -> 0 | L25: =IF(O25="",0,IFERROR(INDEX(Purchases!I:I,MATCH(O25*1,Purchases!A:A,0)),0)) -> 0 | M25: =IF(G25="",0,K25-L25) -> 0 | N25: =IFERROR(IF(G25="","",M25/G25),"") | S25: =IFERROR(VLOOKUP(H25,Settings!B14:C25,2,FALSE()),0) -> 0
A26: =IF(B26="","",ROW()-3) | I26: =IF(G26="",0,G26*S26) -> 0 | K26: =IF(G26="",0,G26-I26-IF(J26="",0,J26)) -> 0 | L26: =IF(O26="",0,IFERROR(INDEX(Purchases!I:I,MATCH(O26*1,Purchases!A:A,0)),0)) -> 0 | M26: =IF(G26="",0,K26-L26) -> 0 | N26: =IFERROR(IF(G26="","",M26/G26),"") | S26: =IFERROR(VLOOKUP(H26,Settings!B14:C25,2,FALSE()),0) -> 0
A27: =IF(B27="","",ROW()-3) | I27: =IF(G27="",0,G27*S27) -> 0 | K27: =IF(G27="",0,G27-I27-IF(J27="",0,J27)) -> 0 | L27: =IF(O27="",0,IFERROR(INDEX(Purchases!I:I,MATCH(O27*1,Purchases!A:A,0)),0)) -> 0 | M27: =IF(G27="",0,K27-L27) -> 0 | N27: =IFERROR(IF(G27="","",M27/G27),"") | S27: =IFERROR(VLOOKUP(H27,Settings!B14:C25,2,FALSE()),0) -> 0
A28: =IF(B28="","",ROW()-3) | I28: =IF(G28="",0,G28*S28) -> 0 | K28: =IF(G28="",0,G28-I28-IF(J28="",0,J28)) -> 0 | L28: =IF(O28="",0,IFERROR(INDEX(Purchases!I:I,MATCH(O28*1,Purchases!A:A,0)),0)) -> 0 | M28: =IF(G28="",0,K28-L28) -> 0 | N28: =IFERROR(IF(G28="","",M28/G28),"") | S28: =IFERROR(VLOOKUP(H28,Settings!B14:C25,2,FALSE()),0) -> 0
A29: =IF(B29="","",ROW()-3) | I29: =IF(G29="",0,G29*S29) -> 0 | K29: =IF(G29="",0,G29-I29-IF(J29="",0,J29)) -> 0 | L29: =IF(O29="",0,IFERROR(INDEX(Purchases!I:I,MATCH(O29*1,Purchases!A:A,0)),0)) -> 0 | M29: =IF(G29="",0,K29-L29) -> 0 | N29: =IFERROR(IF(G29="","",M29/G29),"") | S29: =IFERROR(VLOOKUP(H29,Settings!B14:C25,2,FALSE()),0) -> 0
A30: =IF(B30="","",ROW()-3) | I30: =IF(G30="",0,G30*S30) -> 0 | K30: =IF(G30="",0,G30-I30-IF(J30="",0,J30)) -> 0 | L30: =IF(O30="",0,IFERROR(INDEX(Purchases!I:I,MATCH(O30*1,Purchases!A:A,0)),0)) -> 0 | M30: =IF(G30="",0,K30-L30) -> 0 | N30: =IFERROR(IF(G30="","",M30/G30),"") | S30: =IFERROR(VLOOKUP(H30,Settings!B14:C25,2,FALSE()),0) -> 0
A31: =IF(B31="","",ROW()-3) | I31: =IF(G31="",0,G31*S31) -> 0 | K31: =IF(G31="",0,G31-I31-IF(J31="",0,J31)) -> 0 | L31: =IF(O31="",0,IFERROR(INDEX(Purchases!I:I,MATCH(O31*1,Purchases!A:A,0)),0)) -> 0 | M31: =IF(G31="",0,K31-L31) -> 0 | N31: =IFERROR(IF(G31="","",M31/G31),"") | S31: =IFERROR(VLOOKUP(H31,Settings!B14:C25,2,FALSE()),0) -> 0
A32: =IF(B32="","",ROW()-3) | I32: =IF(G32="",0,G32*S32) -> 0 | K32: =IF(G32="",0,G32-I32-IF(J32="",0,J32)) -> 0 | L32: =IF(O32="",0,IFERROR(INDEX(Purchases!I:I,MATCH(O32*1,Purchases!A:A,0)),0)) -> 0 | M32: =IF(G32="",0,K32-L32) -> 0 | N32: =IFERROR(IF(G32="","",M32/G32),"") | S32: =IFERROR(VLOOKUP(H32,Settings!B14:C25,2,FALSE()),0) -> 0
A33: =IF(B33="","",ROW()-3) | I33: =IF(G33="",0,G33*S33) -> 0 | K33: =IF(G33="",0,G33-I33-IF(J33="",0,J33)) -> 0 | L33: =IF(O33="",0,IFERROR(INDEX(Purchases!I:I,MATCH(O33*1,Purchases!A:A,0)),0)) -> 0 | M33: =IF(G33="",0,K33-L33) -> 0 | N33: =IFERROR(IF(G33="","",M33/G33),"") | S33: =IFERROR(VLOOKUP(H33,Settings!B14:C25,2,FALSE()),0) -> 0
A34: =IF(B34="","",ROW()-3) | I34: =IF(G34="",0,G34*S34) -> 0 | K34: =IF(G34="",0,G34-I34-IF(J34="",0,J34)) -> 0 | L34: =IF(O34="",0,IFERROR(INDEX(Purchases!I:I,MATCH(O34*1,Purchases!A:A,0)),0)) -> 0 | M34: =IF(G34="",0,K34-L34) -> 0 | N34: =IFERROR(IF(G34="","",M34/G34),"") | S34: =IFERROR(VLOOKUP(H34,Settings!B14:C25,2,FALSE()),0) -> 0
A35: =IF(B35="","",ROW()-3) | I35: =IF(G35="",0,G35*S35) -> 0 | K35: =IF(G35="",0,G35-I35-IF(J35="",0,J35)) -> 0 | L35: =IF(O35="",0,IFERROR(INDEX(Purchases!I:I,MATCH(O35*1,Purchases!A:A,0)),0)) -> 0 | M35: =IF(G35="",0,K35-L35) -> 0 | N35: =IFERROR(IF(G35="","",M35/G35),"") | S35: =IFERROR(VLOOKUP(H35,Settings!B14:C25,2,FALSE()),0) -> 0
A36: =IF(B36="","",ROW()-3) | I36: =IF(G36="",0,G36*S36) -> 0 | K36: =IF(G36="",0,G36-I36-IF(J36="",0,J36)) -> 0 | L36: =IF(O36="",0,IFERROR(INDEX(Purchases!I:I,MATCH(O36*1,Purchases!A:A,0)),0)) -> 0 | M36: =IF(G36="",0,K36-L36) -> 0 | N36: =IFERROR(IF(G36="","",M36/G36),"") | S36: =IFERROR(VLOOKUP(H36,Settings!B14:C25,2,FALSE()),0) -> 0
A37: =IF(B37="","",ROW()-3) | I37: =IF(G37="",0,G37*S37) -> 0 | K37: =IF(G37="",0,G37-I37-IF(J37="",0,J37)) -> 0 | L37: =IF(O37="",0,IFERROR(INDEX(Purchases!I:I,MATCH(O37*1,Purchases!A:A,0)),0)) -> 0 | M37: =IF(G37="",0,K37-L37) -> 0 | N37: =IFERROR(IF(G37="","",M37/G37),"") | S37: =IFERROR(VLOOKUP(H37,Settings!B14:C25,2,FALSE()),0) -> 0
A38: =IF(B38="","",ROW()-3) | I38: =IF(G38="",0,G38*S38) -> 0 | K38: =IF(G38="",0,G38-I38-IF(J38="",0,J38)) -> 0 | L38: =IF(O38="",0,IFERROR(INDEX(Purchases!I:I,MATCH(O38*1,Purchases!A:A,0)),0)) -> 0 | M38: =IF(G38="",0,K38-L38) -> 0 | N38: =IFERROR(IF(G38="","",M38/G38),"") | S38: =IFERROR(VLOOKUP(H38,Settings!B14:C25,2,FALSE()),0) -> 0
A39: =IF(B39="","",ROW()-3) | I39: =IF(G39="",0,G39*S39) -> 0 | K39: =IF(G39="",0,G39-I39-IF(J39="",0,J39)) -> 0 | L39: =IF(O39="",0,IFERROR(INDEX(Purchases!I:I,MATCH(O39*1,Purchases!A:A,0)),0)) -> 0 | M39: =IF(G39="",0,K39-L39) -> 0 | N39: =IFERROR(IF(G39="","",M39/G39),"") | S39: =IFERROR(VLOOKUP(H39,Settings!B14:C25,2,FALSE()),0) -> 0
A40: =IF(B40="","",ROW()-3) | I40: =IF(G40="",0,G40*S40) -> 0 | K40: =IF(G40="",0,G40-I40-IF(J40="",0,J40)) -> 0 | L40: =IF(O40="",0,IFERROR(INDEX(Purchases!I:I,MATCH(O40*1,Purchases!A:A,0)),0)) -> 0 | M40: =IF(G40="",0,K40-L40) -> 0 | N40: =IFERROR(IF(G40="","",M40/G40),"") | S40: =IFERROR(VLOOKUP(H40,Settings!B14:C25,2,FALSE()),0) -> 0
...

Sheet Settings
B2: SETTINGS & CONFIGURATION
B3: v26.0 — Configure your tracker below
B5: GENERAL | F5: QUICK REFERENCE
B6: Your Name / Shop Name | F6: Pack Opening Workflow:
B7: Currency | C7: AUD | F7: 1. Log sealed product in Purchases
B8: Country | C8: Australia | F8: 2. Set Status = "Opened" when opened
B9: Tracker Version | C9: v26.0 | F9: 3. Add pulled cards as new Purchase rows
F10: 4. Set Category = "Single Card"
F11: 5. Enter Parent ID = original purchase ID
B12: SELLING PLATFORMS & FEES | F12: 6. Cost basis = Pack cost ÷ cards pulled
B13: Platform | C13: Fee % | D13: Notes
B14: eBay AU | C14: 0.1325 | D14: TCG cards final value fee | F14: Raw → Slab Workflow:
B15: eBay US | C15: 0.1325 | D15: TCG cards final value fee | F15: 1. Card exists in Purchases (Single Card)
B16: Whatnot | C16: 0.109 | D16: 8% commission + 2.9% processing | F16: 2. Add grading fee as "Grading Fees" row
B17: Facebook Marketplace | C17: 0 | D17: Free for local pickup | F17: 3. Set original card Status = "Graded"
B18: TCGPlayer | C18: 0.1089 | D18: Standard seller level | F18: 4. Sell in Sales as "Graded Card"
B19: Gumtree | C19: 0 | D19: Free listings | F19: 5. COGS = card cost + grading fee
B20: Mercari | C20: 0.1 | D20: 10% flat fee
B21: CardMarket | C21: 0.05 | D21: EU market, varies by level | F21: Selling Workflow:
B22: Direct/Local | C22: 0 | D22: No fees for direct sales | F22: 1. Enter sale in Sales tab
B23: Shopify | C23: 0.029 | D23: 2.9% + payment processing | F23: 2. Select Platform (fee auto-calculated)
B24: Payhip | C24: 0.05 | D24: 5% on free plan | F24: 3. Enter Purchase Ref ID to link COGS
B25: Other | C25: 0 | D25: Enter custom fee | F25: 4. Profit auto-calculates
F26: 5. Update Purchase status to "Sold"
B28: MARKET PRICE APIs
B29: API Provider | C29: API Key | D29: Status / Notes
B30: PokemonTCG.io | D30: Free tier: 20K req/day. Get key: pokemontcg.io
B31: TCGdex | D31: FREE - No key needed. Cardmarket + TCGPlayer
B32: PokemonPriceTracker | D32: Free tier: limited. Best pricing + PSA data
B33: PriceCharting | D33: Historical pricing. Sealed products. Optional
B34: Custom API | D34: Add your own API endpoint
B36: Active Price Source | C36: PokemonTCG.io
B40: VERSION & DATA MIGRATION
B41: Current Version | C41: v26.0
B42: Last Migration Date | C42: N/A - First Install
B43: Data Export Format | C43: JSON
B45: ⚡ MIGRATION: Use Apps Script menu → Kollekt → Export Data to save as JSON.
B46: ⚡ IMPORT: In the new version, use Kollekt → Import Data to restore.
B47: ⚡ RESET: Use Kollekt → Reset Tracker to clear all data and restart.

Sheet Guide
B2: KOLLEKT.GG TRACKER — GETTING STARTED GUIDE
B5: WELCOME TO YOUR FINANCIAL TRACKER
B6: This spreadsheet tracks every dollar in and out of your Pokemon TCG hobby/business.
B7: It is NOT a collection tracker — it is a FINANCIAL tracker for serious collector-resellers.
B9: STEP 1: CONFIGURE SETTINGS
B10: → Go to the Settings tab
B11: → Enter your name/shop name
B12: → Select your currency (AUD default)
B13: → Review and adjust platform fee percentages
B14: → Add API keys if you want market price lookups (optional)
B16: STEP 2: INSTALL APPS SCRIPT (Google Sheets only)
B17: → Open Extensions → Apps Script
... B68: Report issues: kollekt.gg
